Workbook

Sheet Synthèse
B3: Mois | C3: Coût Réel | D3: Charge Initiale | E3: Temps passé cumulé | F3: Ecart charge total | G3: Charge Révisée totale | H3: Avancement (%) TP/CI | I3: Coût initial
B4: Septembre | C4: =Septembre!M31 -> 1088 | D4: 120 | E4: =Septembre!F31 -> 16 | F4: =Septembre!I31 -> 0 | G4: =Septembre!H31 -> 115 | H4: =IFERROR(E4/G4,0) -> 0.13913043 | I4: =Septembre!K31 -> 1088
B5: Octobre | C5: =Octobre!M31 -> 1972 | D5: 120 | E5: =Octobre!F31 -> 29 | F5: =Octobre!I31 -> -5 | G5: =Octobre!H31 -> 110 | H5: =IFERROR(E5/G5,0) -> 0.26363636 | I5: =Octobre!K31 -> 2516
B6: Novembre | C6: =Novembre!M31 -> 5372 | D6: 120 | E6: =Novembre!F31 -> 79 | F6: =Novembre!I31 -> -1 | G6: =Novembre!H31 -> 119 | H6: =IFERROR(E6/G6,0) -> 0.66386555 | I6: =Novembre!K31 -> 6188
B7: Décembre | C7: =Décembre!M31 -> 6120 | D7: 120 | E7: =Décembre!F31 -> 90 | F7: =Décembre!I31 -> 1 | G7: =Décembre!H31 -> 121 | H7: =IFERROR(E7/G7,0) -> 0.74380165 | I7: =Décembre!K31 -> 6324
B8: Janvier | C8: =Janvier!M31 -> 5372 | D8: 120 | E8: =Janvier!F31 -> 79 | F8: =Janvier!I31 -> -1 | G8: =Janvier!H31 -> 119 | H8: =IFERROR(E8/G8,0) -> 0.66386555 | I8: =Janvier!K31 -> 6188
B9: Février | C9: =Février!M31 -> 5372 | D9: 120 | E9: =Février!F31 -> 79 | F9: =Février!I31 -> -1 | G9: =Février!H31 -> 119 | H9: =IFERROR(E9/G9,0) -> 0.66386555 | I9: =Février!K31 -> 6188

Sheet Septembre
A1: Phase | B1: Tâche | C1: Qui | D1: Charge Initiale (h) | E1: TPS Période(h) | F1: TPS Cumul (h) | G1: Reste à passer (h) | H1: CR (h) | I1: Ecart de charge (h) | J1: Prix de revien unitaire(€) | K1: Coût Initial (€) | L1: Coût Révisé (€) | M1: Coût Réel | N1: Validation
A2: Initialisation | B2: Fiche d'Ouverture de Projet | C2: Chef de projet | D2: 1 | E2: 1 | F2: =Septembre[[#This Row],[TPS Période(h)]] -> 1 | G2: =IF(N2="Non",MAX(Septembre[[#This Row],[Charge Initiale (h)]]-Septembre[[#This Row],[TPS Cumul (h)]],0),0) -> 0 | H2: =Septembre[[#This Row],[TPS Cumul (h)]]+Septembre[[#This Row],[Reste à passer (h) ]] -> 1 | I2: =Septembre[[#This Row],[CR (h)]] - Septembre[[#This Row],[Charge Initiale (h)]] -> 0 | J2: =IF(Septembre[[#This Row],[Qui]]="Chef de projet","68",IF(Septembre[[#This Row],[Qui]]="Ingénieur Electronique","32",IF(Septembre[[#This Row],[Qui]]="Ingénieur qualité","36",IF(Septembre[[#This Row],[Qui]]="Ingénieur Développement",30,IF(Septembre[[#This Row],[Qui]]="Ingénieur Mécanique",34,""))))) -> 68 | K2: =IF(Septembre[[#This Row],[TPS Cumul (h)]]>0,Septembre[[#This Row],[Charge Initiale (h)]]*Septembre[[#This Row],[Prix de revien unitaire(€)]],0) -> 68 | L2: =Septembre[[#This Row],[CR (h)]]*Septembre[[#This Row],[Prix de revien unitaire(€)]] -> 68 | M2: =Septembre[[#This Row],[Prix de revien unitaire(€)]]*Septembre[[#This Row],[TPS Cumul (h)]] -> 68 | N2: Oui
B3: Plan de développement | C3: Chef de projet | D3: 10 | E3: 9 | F3: =Septembre[[#This Row],[TPS Période(h)]] -> 9 | G3: =IF(N3="Non",MAX(Septembre[[#This Row],[Charge Initiale (h)]]-Septembre[[#This Row],[TPS Cumul (h)]],0),0) -> 0 | H3: =Septembre[[#This Row],[TPS Cumul (h)]]+Septembre[[#This Row],[Reste à passer (h) ]] -> 9 | I3: =Septembre[[#This Row],[CR (h)]] - Septembre[[#This Row],[Charge Initiale (h)]] -> -1 | J3: =IF(Septembre[[#This Row],[Qui]]="Chef de projet","68",IF(Septembre[[#This Row],[Qui]]="Ingénieur Electronique","32",IF(Septembre[[#This Row],[Qui]]="Ingénieur qualité","36",IF(Septembre[[#This Row],[Qui]]="Ingénieur Développement",30,IF(Septembre[[#This Row],[Qui]]="Ingénieur Mécanique",34,""))))) -> 68 | K3: =IF(Septembre[[#This Row],[TPS Cumul (h)]]>0,Septembre[[#This Row],[Charge Initiale (h)]]*Septembre[[#This Row],[Prix de revien unitaire(€)]],0) -> 680 | L3: =Septembre[[#This Row],[CR (h)]]*Septembre[[#This Row],[Prix de revien unitaire(€)]] -> 612 | M3: =Septembre[[#This Row],[Prix de revien unitaire(€)]]*Septembre[[#This Row],[TPS Cumul (h)]] -> 612 | N3: Oui
A4: Spécifications | B4: SPEC | C4: Chef de projet | D4: 5 | E4: 6 | F4: =Septembre[[#This Row],[TPS Période(h)]] -> 6 | G4: =IF(N4="Non",MAX(Septembre[[#This Row],[Charge Initiale (h)]]-Septembre[[#This Row],[TPS Cumul (h)]],0),0) -> 0 | H4: =Septembre[[#This Row],[TPS Cumul (h)]]+Septembre[[#This Row],[Reste à passer (h) ]] -> 6 | I4: =Septembre[[#This Row],[CR (h)]] - Septembre[[#This Row],[Charge Initiale (h)]] -> 1 | J4: =IF(Septembre[[#This Row],[Qui]]="Chef de projet","68",IF(Septembre[[#This Row],[Qui]]="Ingénieur Electronique","32",IF(Septembre[[#This Row],[Qui]]="Ingénieur qualité","36",IF(Septembre[[#This Row],[Qui]]="Ingénieur Développement",30,IF(Septembre[[#This Row],[Qui]]="Ingénieur Mécanique",34,""))))) -> 68 | K4: =IF(Septembre[[#This Row],[TPS Cumul (h)]]>0,Septembre[[#This Row],[Charge Initiale (h)]]*Septembre[[#This Row],[Prix de revien unitaire(€)]],0) -> 340 | L4: =Septembre[[#This Row],[CR (h)]]*Septembre[[#This Row],[Prix de revien unitaire(€)]] -> 408 | M4: =Septembre[[#This Row],[Prix de revien unitaire(€)]]*Septembre[[#This Row],[TPS Cumul (h)]] -> 408 | N4: Oui
B5: Analyse norme IEC61131 | C5: Chef de projet | D5: 1 | E5: 0 | F5: =Septembre[[#This Row],[TPS Période(h)]] -> 0 | G5: =IF(N5="Non",MAX(Septembre[[#This Row],[Charge Initiale (h)]]-Septembre[[#This Row],[TPS Cumul (h)]],0),0) -> 1 | H5: =Septembre[[#This Row],[TPS Cumul (h)]]+Septembre[[#This Row],[Reste à passer (h) ]] -> 1 | I5: =Septembre[[#This Row],[CR (h)]] - Septembre[[#This Row],[Charge Initiale (h)]] -> 0 | J5: =IF(Septembre[[#This Row],[Qui]]="Chef de projet","68",IF(Septembre[[#This Row],[Qui]]="Ingénieur Electronique","32",IF(Septembre[[#This Row],[Qui]]="Ingénieur qualité","36",IF(Septembre[[#This Row],[Qui]]="Ingénieur Développement",30,IF(Septembre[[#This Row],[Qui]]="Ingénieur Mécanique",34,""))))) -> 68 | K5: =IF(Septembre[[#This Row],[TPS Cumul (h)]]>0,Septembre[[#This Row],[Charge Initiale (h)]]*Septembre[[#This Row],[Prix de revien unitaire(€)]],0) -> 0 | L5: =Septembre[[#This Row],[CR (h)]]*Septembre[[#This Row],[Prix de revien unitaire(€)]] -> 68 | M5: =Septembre[[#This Row],[Prix de revien unitaire(€)]]*Septembre[[#This Row],[TPS Cumul (h)]] -> 0 | N5: Non
B6: Analyse norme IEC61499 | C6: Chef de projet | D6: 2 | E6: 0 | F6: =Septembre[[#This Row],[TPS Période(h)]] -> 0 | G6: =IF(N6="Non",MAX(Septembre[[#This Row],[Charge Initiale (h)]]-Septembre[[#This Row],[TPS Cumul (h)]],0),0) -> 2 | H6: =Septembre[[#This Row],[TPS Cumul (h)]]+Septembre[[#This Row],[Reste à passer (h) ]] -> 2 | I6: =Septembre[[#This Row],[CR (h)]] - Septembre[[#This Row],[Charge Initiale (h)]] -> 0 | J6: =IF(Septembre[[#This Row],[Qui]]="Chef de projet","68",IF(Septembre[[#This Row],[Qui]]="Ingénieur Electronique","32",IF(Septembre[[#This Row],[Qui]]="Ingénieur qualité","36",IF(Septembre[[#This Row],[Qui]]="Ingénieur Développement",30,IF(Septembre[[#This Row],[Qui]]="Ingénieur Mécanique",34,""))))) -> 68 | K6: =IF(Septembre[[#This Row],[TPS Cumul (h)]]>0,Septembre[[#This Row],[Charge Initiale (h)]]*Septembre[[#This Row],[Prix de revien unitaire(€)]],0) -> 0 | L6: =Septembre[[#This Row],[CR (h)]]*Septembre[[#This Row],[Prix de revien unitaire(€)]] -> 136 | M6: =Septembre[[#This Row],[Prix de revien unitaire(€)]]*Septembre[[#This Row],[TPS Cumul (h)]] -> 0 | N6: Non
B7: Analyse du fonctionnement du centre de tri de pièce FactoryIO | C7: Chef de projet | D7: 2 | E7: 0 | F7: =Septembre[[#This Row],[TPS Période(h)]] -> 0 | G7: =IF(N7="Non",MAX(Septembre[[#This Row],[Charge Initiale (h)]]-Septembre[[#This Row],[TPS Cumul (h)]],0),0) -> 2 | H7: =Septembre[[#This Row],[TPS Cumul (h)]]+Septembre[[#This Row],[Reste à passer (h) ]] -> 2 | I7: =Septembre[[#This Row],[CR (h)]] - Septembre[[#This Row],[Charge Initiale (h)]] -> 0 | J7: =IF(Septembre[[#This Row],[Qui]]="Chef de projet","68",IF(Septembre[[#This Row],[Qui]]="Ingénieur Electronique","32",IF(Septembre[[#This Row],[Qui]]="Ingénieur qualité","36",IF(Septembre[[#This Row],[Qui]]="Ingénieur Développement",30,IF(Septembre[[#This Row],[Qui]]="Ingénieur Mécanique",34,""))))) -> 68 | K7: =IF(Septembre[[#This Row],[TPS Cumul (h)]]>0,Septembre[[#This Row],[Charge Initiale (h)]]*Septembre[[#This Row],[Prix de revien unitaire(€)]],0) -> 0 | L7: =Septembre[[#This Row],[CR (h)]]*Septembre[[#This Row],[Prix de revien unitaire(€)]] -> 136 | M7: =Septembre[[#This Row],[Prix de revien unitaire(€)]]*Septembre[[#This Row],[TPS Cumul (h)]] -> 0 | N7: Non
B8: Méthodologie de programmation du centre de tri de pièce (Norme IEC61131) | C8: Chef de projet | D8: 2 | E8: 0 | F8: =Septembre[[#This Row],[TPS Période(h)]] -> 0 | G8: =IF(N8="Non",MAX(Septembre[[#This Row],[Charge Initiale (h)]]-Septembre[[#This Row],[TPS Cumul (h)]],0),0) -> 2 | H8: =Septembre[[#This Row],[TPS Cumul (h)]]+Septembre[[#This Row],[Reste à passer (h) ]] -> 2 | I8: =Septembre[[#This Row],[CR (h)]] - Septembre[[#This Row],[Charge Initiale (h)]] -> 0 | J8: =IF(Septembre[[#This Row],[Qui]]="Chef de projet","68",IF(Septembre[[#This Row],[Qui]]="Ingénieur Electronique","32",IF(Septembre[[#This Row],[Qui]]="Ingénieur qualité","36",IF(Septembre[[#This Row],[Qui]]="Ingénieur Développement",30,IF(Septembre[[#This Row],[Qui]]="Ingénieur Mécanique",34,""))))) -> 68 | K8: =IF(Septembre[[#This Row],[TPS Cumul (h)]]>0,Septembre[[#This Row],[Charge Initiale (h)]]*Septembre[[#This Row],[Prix de revien unitaire(€)]],0) -> 0 | L8: =Septembre[[#This Row],[CR (h)]]*Septembre[[#This Row],[Prix de revien unitaire(€)]] -> 136 | M8: =Septembre[[#This Row],[Prix de revien unitaire(€)]]*Septembre[[#This Row],[TPS Cumul (h)]] -> 0 | N8: Non
B9: Méthodologie de programmation du centre de tri de pièce (Norme IEC61499) | C9: Chef de projet | D9: 2 | E9: 0 | F9: =Septembre[[#This Row],[TPS Période(h)]] -> 0 | G9: =IF(N9="Non",MAX(Septembre[[#This Row],[Charge Initiale (h)]]-Septembre[[#This Row],[TPS Cumul (h)]],0),0) -> 2 | H9: =Septembre[[#This Row],[TPS Cumul (h)]]+Septembre[[#This Row],[Reste à passer (h) ]] -> 2 | I9: =Septembre[[#This Row],[CR (h)]] - Septembre[[#This Row],[Charge Initiale (h)]] -> 0 | J9: =IF(Septembre[[#This Row],[Qui]]="Chef de projet","68",IF(Septembre[[#This Row],[Qui]]="Ingénieur Electronique","32",IF(Septembre[[#This Row],[Qui]]="Ingénieur qualité","36",IF(Septembre[[#This Row],[Qui]]="Ingénieur Développement",30,IF(Septembre[[#This Row],[Qui]]="Ingénieur Mécanique",34,""))))) -> 68 | K9: =IF(Septembre[[#This Row],[TPS Cumul (h)]]>0,Septembre[[#This Row],[Charge Initiale (h)]]*Septembre[[#This Row],[Prix de revien unitaire(€)]],0) -> 0 | L9: =Septembre[[#This Row],[CR (h)]]*Septembre[[#This Row],[Prix de revien unitaire(€)]] -> 136 | M9: =Septembre[[#This Row],[Prix de revien unitaire(€)]]*Septembre[[#This Row],[TPS Cumul (h)]] -> 0 | N9: Non
A10: Conception générale | B10: IEC61131 - Grafcet de niveau 1 | C10: Chef de projet | D10: 4 | E10: 0 | F10: =Septembre[[#This Row],[TPS Période(h)]] -> 0 | G10: =IF(N10="Non",MAX(Septembre[[#This Row],[Charge Initiale (h)]]-Septembre[[#This Row],[TPS Cumul (h)]],0),0) -> 4 | H10: =Septembre[[#This Row],[TPS Cumul (h)]]+Septembre[[#This Row],[Reste à passer (h) ]] -> 4 | I10: =Septembre[[#This Row],[CR (h)]] - Septembre[[#This Row],[Charge Initiale (h)]] -> 0 | J10: =IF(Septembre[[#This Row],[Qui]]="Chef de projet","68",IF(Septembre[[#This Row],[Qui]]="Ingénieur Electronique","32",IF(Septembre[[#This Row],[Qui]]="Ingénieur qualité","36",IF(Septembre[[#This Row],[Qui]]="Ingénieur Développement",30,IF(Septembre[[#This Row],[Qui]]="Ingénieur Mécanique",34,""))))) -> 68 | K10: =IF(Septembre[[#This Row],[TPS Cumul (h)]]>0,Septembre[[#This Row],[Charge Initiale (h)]]*Septembre[[#This Row],[Prix de revien unitaire(€)]],0) -> 0 | L10: =Septembre[[#This Row],[CR (h)]]*Septembre[[#This Row],[Prix de revien unitaire(€)]] -> 272 | M10: =Septembre[[#This Row],[Prix de revien unitaire(€)]]*Septembre[[#This Row],[TPS Cumul (h)]] -> 0 | N10: Non
B11: IEC61499 - Bloc fonctionnel général | C11: Chef de projet | D11: 4 | E11: 0 | F11: =Septembre[[#This Row],[TPS Période(h)]] -> 0 | G11: =IF(N11="Non",MAX(Septembre[[#This Row],[Charge Initiale (h)]]-Septembre[[#This Row],[TPS Cumul (h)]],0),0) -> 4 | H11: =Septembre[[#This Row],[TPS Cumul (h)]]+Septembre[[#This Row],[Reste à passer (h) ]] -> 4 | I11: =Septembre[[#This Row],[CR (h)]] - Septembre[[#This Row],[Charge Initiale (h)]] -> 0 | J11: =IF(Septembre[[#This Row],[Qui]]="Chef de projet","68",IF(Septembre[[#This Row],[Qui]]="Ingénieur Electronique","32",IF(Septembre[[#This Row],[Qui]]="Ingénieur qualité","36",IF(Septembre[[#This Row],[Qui]]="Ingénieur Développement",30,IF(Septembre[[#This Row],[Qui]]="Ingénieur Mécanique",34,""))))) -> 68 | K11: =IF(Septembre[[#This Row],[TPS Cumul (h)]]>0,Septembre[[#This Row],[Charge Initiale (h)]]*Septembre[[#This Row],[Prix de revien unitaire(€)]],0) -> 0 | L11: =Septembre[[#This Row],[CR (h)]]*Septembre[[#This Row],[Prix de revien unitaire(€)]] -> 272 | M11: =Septembre[[#This Row],[Prix de revien unitaire(€)]]*Septembre[[#This Row],[TPS Cumul (h)]] -> 0 | N11: Non
B12: Fonctionnement général du centre de tri de pièce | C12: Chef de projet | D12: 1 | E12: 0 | F12: =Septembre[[#This Row],[TPS Période(h)]] -> 0 | G12: =IF(N12="Non",MAX(Septembre[[#This Row],[Charge Initiale (h)]]-Septembre[[#This Row],[TPS Cumul (h)]],0),0) -> 1 | H12: =Septembre[[#This Row],[TPS Cumul (h)]]+Septembre[[#This Row],[Reste à passer (h) ]] -> 1 | I12: =Septembre[[#This Row],[CR (h)]] - Septembre[[#This Row],[Charge Initiale (h)]] -> 0 | J12: =IF(Septembre[[#This Row],[Qui]]="Chef de projet","68",IF(Septembre[[#This Row],[Qui]]="Ingénieur Electronique","32",IF(Septembre[[#This Row],[Qui]]="Ingénieur qualité","36",IF(Septembre[[#This Row],[Qui]]="Ingénieur Développement",30,IF(Septembre[[#This Row],[Qui]]="Ingénieur Mécanique",34,""))))) -> 68 | K12: =IF(Septembre[[#This Row],[TPS Cumul (h)]]>0,Septembre[[#This Row],[Charge Initiale (h)]]*Septembre[[#This Row],[Prix de revien unitaire(€)]],0) -> 0 | L12: =Septembre[[#This Row],[CR (h)]]*Septembre[[#This Row],[Prix de revien unitaire(€)]] -> 68 | M12: =Septembre[[#This Row],[Prix de revien unitaire(€)]]*Septembre[[#This Row],[TPS Cumul (h)]] -> 0 | N12: Non
B13: Liste des capteurs Centre de tri de pièce | C13: Chef de projet | D13: 2 | E13: 0 | F13: =Septembre[[#This Row],[TPS Période(h)]] -> 0 | G13: =IF(N13="Non",MAX(Septembre[[#This Row],[Charge Initiale (h)]]-Septembre[[#This Row],[TPS Cumul (h)]],0),0) -> 2 | H13: =Septembre[[#This Row],[TPS Cumul (h)]]+Septembre[[#This Row],[Reste à passer (h) ]] -> 2 | I13: =Septembre[[#This Row],[CR (h)]] - Septembre[[#This Row],[Charge Initiale (h)]] -> 0 | J13: =IF(Septembre[[#This Row],[Qui]]="Chef de projet","68",IF(Septembre[[#This Row],[Qui]]="Ingénieur Electronique","32",IF(Septembre[[#This Row],[Qui]]="Ingénieur qualité","36",IF(Septembre[[#This Row],[Qui]]="Ingénieur Développement",30,IF(Septembre[[#This Row],[Qui]]="Ingénieur Mécanique",34,""))))) -> 68 | K13: =IF(Septembre[[#This Row],[TPS Cumul (h)]]>0,Septembre[[#This Row],[Charge Initiale (h)]]*Septembre[[#This Row],[Prix de revien unitaire(€)]],0) -> 0 | L13: =Septembre[[#This Row],[CR (h)]]*Septembre[[#This Row],[Prix de revien unitaire(€)]] -> 136 | M13: =Septembre[[#This Row],[Prix de revien unitaire(€)]]*Septembre[[#This Row],[TPS Cumul (h)]] -> 0 | N13: Non
A14: Conception détaillé | B14: IEC 61499 - Bloc fonctionnel détaillée | C14: Chef de projet | D14: 7 | E14: 0 | F14: =Septembre[[#This Row],[TPS Période(h)]] -> 0 | G14: =IF(N14="Non",MAX(Septembre[[#This Row],[Charge Initiale (h)]]-Septembre[[#This Row],[TPS Cumul (h)]],0),0) -> 7 | H14: =Septembre[[#This Row],[TPS Cumul (h)]]+Septembre[[#This Row],[Reste à passer (h) ]] -> 7 | I14: =Septembre[[#This Row],[CR (h)]] - Septembre[[#This Row],[Charge Initiale (h)]] -> 0 | J14: =IF(Septembre[[#This Row],[Qui]]="Chef de projet","68",IF(Septembre[[#This Row],[Qui]]="Ingénieur Electronique","32",IF(Septembre[[#This Row],[Qui]]="Ingénieur qualité","36",IF(Septembre[[#This Row],[Qui]]="Ingénieur Développement",30,IF(Septembre[[#This Row],[Qui]]="Ingénieur Mécanique",34,""))))) -> 68 | K14: =IF(Septembre[[#This Row],[TPS Cumul (h)]]>0,Septembre[[#This Row],[Charge Initiale (h)]]*Septembre[[#This Row],[Prix de revien unitaire(€)]],0) -> 0 | L14: =Septembre[[#This Row],[CR (h)]]*Septembre[[#This Row],[Prix de revien unitaire(€)]] -> 476 | M14: =Septembre[[#This Row],[Prix de revien unitaire(€)]]*Septembre[[#This Row],[TPS Cumul (h)]] -> 0 | N14: Non
B15: IEC 61131 - Grafcet de niveau 2 | C15: Chef de projet | D15: 7 | E15: 0 | F15: =Septembre[[#This Row],[TPS Période(h)]] -> 0 | G15: =IF(N15="Non",MAX(Septembre[[#This Row],[Charge Initiale (h)]]-Septembre[[#This Row],[TPS Cumul (h)]],0),0) -> 7 | H15: =Septembre[[#This Row],[TPS Cumul (h)]]+Septembre[[#This Row],[Reste à passer (h) ]] -> 7 | I15: =Septembre[[#This Row],[CR (h)]] - Septembre[[#This Row],[Charge Initiale (h)]] -> 0 | J15: =IF(Septembre[[#This Row],[Qui]]="Chef de projet","68",IF(Septembre[[#This Row],[Qui]]="Ingénieur Electronique","32",IF(Septembre[[#This Row],[Qui]]="Ingénieur qualité","36",IF(Septembre[[#This Row],[Qui]]="Ingénieur Développement",30,IF(Septembre[[#This Row],[Qui]]="Ingénieur Mécanique",34,""))))) -> 68 | K15: =IF(Septembre[[#This Row],[TPS Cumul (h)]]>0,Septembre[[#This Row],[Charge Initiale (h)]]*Septembre[[#This Row],[Prix de revien unitaire(€)]],0) -> 0 | L15: =Septembre[[#This Row],[CR (h)]]*Septembre[[#This Row],[Prix de revien unitaire(€)]] -> 476 | M15: =Septembre[[#This Row],[Prix de revien unitaire(€)]]*Septembre[[#This Row],[TPS Cumul (h)]] -> 0 | N15: Non
B16: Fonctionnement détaillé du centre de tri de pièce FactoryIO | C16: Chef de projet | D16: 4 | E16: 0 | F16: =Septembre[[#This Row],[TPS Période(h)]] -> 0 | G16: =IF(N16="Non",MAX(Septembre[[#This Row],[Charge Initiale (h)]]-Septembre[[#This Row],[TPS Cumul (h)]],0),0) -> 4 | H16: =Septembre[[#This Row],[TPS Cumul (h)]]+Septembre[[#This Row],[Reste à passer (h) ]] -> 4 | I16: =Septembre[[#This Row],[CR (h)]] - Septembre[[#This Row],[Charge Initiale (h)]] -> 0 | J16: =IF(Septembre[[#This Row],[Qui]]="Chef de projet","68",IF(Septembre[[#This Row],[Qui]]="Ingénieur Electronique","32",IF(Septembre[[#This Row],[Qui]]="Ingénieur qualité","36",IF(Septembre[[#This Row],[Qui]]="Ingénieur Développement",30,IF(Septembre[[#This Row],[Qui]]="Ingénieur Mécanique",34,""))))) -> 68 | K16: =IF(Septembre[[#This Row],[TPS Cumul (h)]]>0,Septembre[[#This Row],[Charge Initiale (h)]]*Septembre[[#This Row],[Prix de revien unitaire(€)]],0) -> 0 | L16: =Septembre[[#This Row],[CR (h)]]*Septembre[[#This Row],[Prix de revien unitaire(€)]] -> 272 | M16: =Septembre[[#This Row],[Prix de revien unitaire(€)]]*Septembre[[#This Row],[TPS Cumul (h)]] -> 0 | N16: Non
B17: Tâble des variables centre de tri de pièce FactoryIO | C17: Chef de projet | D17: 3 | E17: 0 | F17: =Septembre[[#This Row],[TPS Période(h)]] -> 0 | G17: =IF(N17="Non",MAX(Septembre[[#This Row],[Charge Initiale (h)]]-Septembre[[#This Row],[TPS Cumul (h)]],0),0) -> 3 | H17: =Septembre[[#This Row],[TPS Cumul (h)]]+Septembre[[#This Row],[Reste à passer (h) ]] -> 3 | I17: =Septembre[[#This Row],[CR (h)]] - Septembre[[#This Row],[Charge Initiale (h)]] -> 0 | J17: =IF(Septembre[[#This Row],[Qui]]="Chef de projet","68",IF(Septembre[[#This Row],[Qui]]="Ingénieur Electronique","32",IF(Septembre[[#This Row],[Qui]]="Ingénieur qualité","36",IF(Septembre[[#This Row],[Qui]]="Ingénieur Développement",30,IF(Septembre[[#This Row],[Qui]]="Ingénieur Mécanique",34,""))))) -> 68 | K17: =IF(Septembre[[#This Row],[TPS Cumul (h)]]>0,Septembre[[#This Row],[Charge Initiale (h)]]*Septembre[[#This Row],[Prix de revien unitaire(€)]],0) -> 0 | L17: =Septembre[[#This Row],[CR (h)]]*Septembre[[#This Row],[Prix de revien unitaire(€)]] -> 204 | M17: =Septembre[[#This Row],[Prix de revien unitaire(€)]]*Septembre[[#This Row],[TPS Cumul (h)]] -> 0 | N17: Non
A18: Réalisation | B18: Programmation du centre de tri de pièce sur ECE | C18: Chef de projet | D18: 10 | E18: 0 | F18: =Septembre[[#This Row],[TPS Période(h)]] -> 0 | G18: =IF(N18="Non",MAX(Septembre[[#This Row],[Charge Initiale (h)]]-Septembre[[#This Row],[TPS Cumul (h)]],0),0) -> 10 | H18: =Septembre[[#This Row],[TPS Cumul (h)]]+Septembre[[#This Row],[Reste à passer (h) ]] -> 10 | I18: =Septembre[[#This Row],[CR (h)]] - Septembre[[#This Row],[Charge Initiale (h)]] -> 0 | J18: =IF(Septembre[[#This Row],[Qui]]="Chef de projet","68",IF(Septembre[[#This Row],[Qui]]="Ingénieur Electronique","32",IF(Septembre[[#This Row],[Qui]]="Ingénieur qualité","36",IF(Septembre[[#This Row],[Qui]]="Ingénieur Développement",30,IF(Septembre[[#This Row],[Qui]]="Ingénieur Mécanique",34,""))))) -> 68 | K18: =IF(Septembre[[#This Row],[TPS Cumul (h)]]>0,Septembre[[#This Row],[Charge Initiale (h)]]*Septembre[[#This Row],[Prix de revien unitaire(€)]],0) -> 0 | L18: =Septembre[[#This Row],[CR (h)]]*Septembre[[#This Row],[Prix de revien unitaire(€)]] -> 680 | M18: =Septembre[[#This Row],[Prix de revien unitaire(€)]]*Septembre[[#This Row],[TPS Cumul (h)]] -> 0 | N18: Non
B19: Programmation du centre de tri de pièce sur EAE | C19: Chef de projet | D19: 10 | E19: 0 | F19: =Septembre[[#This Row],[TPS Période(h)]] -> 0 | G19: =IF(N19="Non",MAX(Septembre[[#This Row],[Charge Initiale (h)]]-Septembre[[#This Row],[TPS Cumul (h)]],0),0) -> 10 | H19: =Septembre[[#This Row],[TPS Cumul (h)]]+Septembre[[#This Row],[Reste à passer (h) ]] -> 10 | I19: =Septembre[[#This Row],[CR (h)]] - Septembre[[#This Row],[Charge Initiale (h)]] -> 0 | J19: =IF(Septembre[[#This Row],[Qui]]="Chef de projet","68",IF(Septembre[[#This Row],[Qui]]="Ingénieur Electronique","32",IF(Septembre[[#This Row],[Qui]]="Ingénieur qualité","36",IF(Septembre[[#This Row],[Qui]]="Ingénieur Développement",30,IF(Septembre[[#This Row],[Qui]]="Ingénieur Mécanique",34,""))))) -> 68 | K19: =IF(Septembre[[#This Row],[TPS Cumul (h)]]>0,Septembre[[#This Row],[Charge Initiale (h)]]*Septembre[[#This Row],[Prix de revien unitaire(€)]],0) -> 0 | L19: =Septembre[[#This Row],[CR (h)]]*Septembre[[#This Row],[Prix de revien unitaire(€)]] -> 680 | M19: =Septembre[[#This Row],[Prix de revien unitaire(€)]]*Septembre[[#This Row],[TPS Cumul (h)]] -> 0 | N19: Non
B20: Rédaction du document de méthodologie de programmation sur la norme IEC61499 | C20: Chef de projet | D20: 3 | E20: 0 | F20: =Septembre[[#This Row],[TPS Période(h)]] -> 0 | G20: =IF(N20="Non",MAX(Septembre[[#This Row],[Charge Initiale (h)]]-Septembre[[#This Row],[TPS Cumul (h)]],0),0) -> 3 | H20: =Septembre[[#This Row],[TPS Cumul (h)]]+Septembre[[#This Row],[Reste à passer (h) ]] -> 3 | I20: =Septembre[[#This Row],[CR (h)]] - Septembre[[#This Row],[Charge Initiale (h)]] -> 0 | J20: =IF(Septembre[[#This Row],[Qui]]="Chef de projet","68",IF(Septembre[[#This Row],[Qui]]="Ingénieur Electronique","32",IF(Septembre[[#This Row],[Qui]]="Ingénieur qualité","36",IF(Septembre[[#This Row],[Qui]]="Ingénieur Développement",30,IF(Septembre[[#This Row],[Qui]]="Ingénieur Mécanique",34,""))))) -> 68 | K20: =IF(Septembre[[#This Row],[TPS Cumul (h)]]>0,Septembre[[#This Row],[Charge Initiale (h)]]*Septembre[[#This Row],[Prix de revien unitaire(€)]],0) -> 0 | L20: =Septembre[[#This Row],[CR (h)]]*Septembre[[#This Row],[Prix de revien unitaire(€)]] -> 204 | M20: =Septembre[[#This Row],[Prix de revien unitaire(€)]]*Septembre[[#This Row],[TPS Cumul (h)]] -> 0 | N20: Non
B21: Correction (optionnel) | C21: Chef de projet | D21: 7 | E21: 0 | F21: =Septembre[[#This Row],[TPS Période(h)]] -> 0 | G21: =IF(N21="Non",MAX(Septembre[[#This Row],[Charge Initiale (h)]]-Septembre[[#This Row],[TPS Cumul (h)]],0),0) -> 7 | H21: =Septembre[[#This Row],[TPS Cumul (h)]]+Septembre[[#This Row],[Reste à passer (h) ]] -> 7 | I21: =Septembre[[#This Row],[CR (h)]] - Septembre[[#This Row],[Charge Initiale (h)]] -> 0 | J21: =IF(Septembre[[#This Row],[Qui]]="Chef de projet","68",IF(Septembre[[#This Row],[Qui]]="Ingénieur Electronique","32",IF(Septembre[[#This Row],[Qui]]="Ingénieur qualité","36",IF(Septembre[[#This Row],[Qui]]="Ingénieur Développement",30,IF(Septembre[[#This Row],[Qui]]="Ingénieur Mécanique",34,""))))) -> 68 | K21: =IF(Septembre[[#This Row],[TPS Cumul (h)]]>0,Septembre[[#This Row],[Charge Initiale (h)]]*Septembre[[#This Row],[Prix de revien unitaire(€)]],0) -> 0 | L21: =Septembre[[#This Row],[CR (h)]]*Septembre[[#This Row],[Prix de revien unitaire(€)]] -> 476 | M21: =Septembre[[#This Row],[Prix de revien unitaire(€)]]*Septembre[[#This Row],[TPS Cumul (h)]] -> 0 | N21: Non
A22: Tests unitaires | B22: Test unitaire programme EAE | C22: Chef de projet | D22: 7 | E22: 0 | F22: =Septembre[[#This Row],[TPS Période(h)]] -> 0 | G22: =IF(N22="Non",MAX(Septembre[[#This Row],[Charge Initiale (h)]]-Septembre[[#This Row],[TPS Cumul (h)]],0),0) -> 7 | H22: =Septembre[[#This Row],[TPS Cumul (h)]]+Septembre[[#This Row],[Reste à passer (h) ]] -> 7 | I22: =Septembre[[#This Row],[CR (h)]] - Septembre[[#This Row],[Charge Initiale (h)]] -> 0 | J22: =IF(Septembre[[#This Row],[Qui]]="Chef de projet","68",IF(Septembre[[#This Row],[Qui]]="Ingénieur Electronique","32",IF(Septembre[[#This Row],[Qui]]="Ingénieur qualité","36",IF(Septembre[[#This Row],[Qui]]="Ingénieur Développement",30,IF(Septembre[[#This Row],[Qui]]="Ingénieur Mécanique",34,""))))) -> 68 | K22: =IF(Septembre[[#This Row],[TPS Cumul (h)]]>0,Septembre[[#This Row],[Charge Initiale (h)]]*Septembre[[#This Row],[Prix de revien unitaire(€)]],0) -> 0 | L22: =Septembre[[#This Row],[CR (h)]]*Septembre[[#This Row],[Prix de revien unitaire(€)]] -> 476 | M22: =Septembre[[#This Row],[Prix de revien unitaire(€)]]*Septembre[[#This Row],[TPS Cumul (h)]] -> 0 | N22: Non
B23: Test unitaire programme ECE | C23: Chef de projet | D23: 2 | E23: 0 | F23: =Septembre[[#This Row],[TPS Période(h)]] -> 0 | G23: =IF(N23="Non",MAX(Septembre[[#This Row],[Charge Initiale (h)]]-Septembre[[#This Row],[TPS Cumul (h)]],0),0) -> 2 | H23: =Septembre[[#This Row],[TPS Cumul (h)]]+Septembre[[#This Row],[Reste à passer (h) ]] -> 2 | I23: =Septembre[[#This Row],[CR (h)]] - Septembre[[#This Row],[Charge Initiale (h)]] -> 0 | J23: =IF(Septembre[[#This Row],[Qui]]="Chef de projet","68",IF(Septembre[[#This Row],[Qui]]="Ingénieur Electronique","32",IF(Septembre[[#This Row],[Qui]]="Ingénieur qualité","36",IF(Septembre[[#This Row],[Qui]]="Ingénieur Développement",30,IF(Septembre[[#This Row],[Qui]]="Ingénieur Mécanique",34,""))))) -> 68 | K23: =IF(Septembre[[#This Row],[TPS Cumul (h)]]>0,Septembre[[#This Row],[Charge Initiale (h)]]*Septembre[[#This Row],[Prix de revien unitaire(€)]],0) -> 0 | L23: =Septembre[[#This Row],[CR (h)]]*Septembre[[#This Row],[Prix de revien unitaire(€)]] -> 136 | M23: =Septembre[[#This Row],[Prix de revien unitaire(€)]]*Septembre[[#This Row],[TPS Cumul (h)]] -> 0 | N23: Non
A24: Test d'intégration | B24: Test d'intégration FactoryIO et programme ECE | C24: Chef de projet | D24: 2 | E24: 0 | F24: =Septembre[[#This Row],[TPS Période(h)]] -> 0 | G24: =IF(N24="Non",MAX(Septembre[[#This Row],[Charge Initiale (h)]]-Septembre[[#This Row],[TPS Cumul (h)]],0),0) -> 2 | H24: =Septembre[[#This Row],[TPS Cumul (h)]]+Septembre[[#This Row],[Reste à passer (h) ]] -> 2 | I24: =Septembre[[#This Row],[CR (h)]] - Septembre[[#This Row],[Charge Initiale (h)]] -> 0 | J24: =IF(Septembre[[#This Row],[Qui]]="Chef de projet","68",IF(Septembre[[#This Row],[Qui]]="Ingénieur Electronique","32",IF(Septembre[[#This Row],[Qui]]="Ingénieur qualité","36",IF(Septembre[[#This Row],[Qui]]="Ingénieur Développement",30,IF(Septembre[[#This Row],[Qui]]="Ingénieur Mécanique",34,""))))) -> 68 | K24: =IF(Septembre[[#This Row],[TPS Cumul (h)]]>0,Septembre[[#This Row],[Charge Initiale (h)]]*Septembre[[#This Row],[Prix de revien unitaire(€)]],0) -> 0 | L24: =Septembre[[#This Row],[CR (h)]]*Septembre[[#This Row],[Prix de revien unitaire(€)]] -> 136 | M24: =Septembre[[#This Row],[Prix de revien unitaire(€)]]*Septembre[[#This Row],[TPS Cumul (h)]] -> 0 | N24: Non
B25: Test d'intégration FactoryIO et programme EAE | C25: Chef de projet | D25: 2 | E25: 0 | F25: =Septembre[[#This Row],[TPS Période(h)]] -> 0 | G25: =IF(N25="Non",MAX(Septembre[[#This Row],[Charge Initiale (h)]]-Septembre[[#This Row],[TPS Cumul (h)]],0),0) -> 2 | H25: =Septembre[[#This Row],[TPS Cumul (h)]]+Septembre[[#This Row],[Reste à passer (h) ]] -> 2 | I25: =Septembre[[#This Row],[CR (h)]] - Septembre[[#This Row],[Charge Initiale (h)]] -> 0 | J25: =IF(Septembre[[#This Row],[Qui]]="Chef de projet","68",IF(Septembre[[#This Row],[Qui]]="Ingénieur Electronique","32",IF(Septembre[[#This Row],[Qui]]="Ingénieur qualité","36",IF(Septembre[[#This Row],[Qui]]="Ingénieur Développement",30,IF(Septembre[[#This Row],[Qui]]="Ingénieur Mécanique",34,""))))) -> 68 | K25: =IF(Septembre[[#This Row],[TPS Cumul (h)]]>0,Septembre[[#This Row],[Charge Initiale (h)]]*Septembre[[#This Row],[Prix de revien unitaire(€)]],0) -> 0 | L25: =Septembre[[#This Row],[CR (h)]]*Septembre[[#This Row],[Prix de revien unitaire(€)]] -> 136 | M25: =Septembre[[#This Row],[Prix de revien unitaire(€)]]*Septembre[[#This Row],[TPS Cumul (h)]] -> 0 | N25: Non
A26: Validation | B26: Validation du fonctionnement avec le client | C26: Chef de projet | D26: 10 | E26: 0 | F26: =Septembre[[#This Row],[TPS Période(h)]] -> 0 | G26: =IF(N26="Non",MAX(Septembre[[#This Row],[Charge Initiale (h)]]-Septembre[[#This Row],[TPS Cumul (h)]],0),0) -> 10 | H26: =Septembre[[#This Row],[TPS Cumul (h)]]+Septembre[[#This Row],[Reste à passer (h) ]] -> 10 | I26: =Septembre[[#This Row],[CR (h)]] - Septembre[[#This Row],[Charge Initiale (h)]] -> 0 | J26: =IF(Septembre[[#This Row],[Qui]]="Chef de projet","68",IF(Septembre[[#This Row],[Qui]]="Ingénieur Electronique","32",IF(Septembre[[#This Row],[Qui]]="Ingénieur qualité","36",IF(Septembre[[#This Row],[Qui]]="Ingénieur Développement",30,IF(Septembre[[#This Row],[Qui]]="Ingénieur Mécanique",34,""))))) -> 68 | K26: =IF(Septembre[[#This Row],[TPS Cumul (h)]]>0,Septembre[[#This Row],[Charge Initiale (h)]]*Septembre[[#This Row],[Prix de revien unitaire(€)]],0) -> 0 | L26: =Septembre[[#This Row],[CR (h)]]*Septembre[[#This Row],[Prix de revien unitaire(€)]] -> 680 | M26: =Septembre[[#This Row],[Prix de revien unitaire(€)]]*Septembre[[#This Row],[TPS Cumul (h)]] -> 0 | N26: Non
B27: Validation du document de comparaison par le client | C27: Chef de projet | D27: 2 | E27: 0 | F27: =Septembre[[#This Row],[TPS Période(h)]] -> 0 | G27: =IF(N27="Non",MAX(Septembre[[#This Row],[Charge Initiale (h)]]-Septembre[[#This Row],[TPS Cumul (h)]],0),0) -> 2 | H27: =Septembre[[#This Row],[TPS Cumul (h)]]+Septembre[[#This Row],[Reste à passer (h) ]] -> 2 | I27: =Septembre[[#This Row],[CR (h)]] - Septembre[[#This Row],[Charge Initiale (h)]] -> 0 | J27: =IF(Septembre[[#This Row],[Qui]]="Chef de projet","68",IF(Septembre[[#This Row],[Qui]]="Ingénieur Electronique","32",IF(Septembre[[#This Row],[Qui]]="Ingénieur qualité","36",IF(Septembre[[#This Row],[Qui]]="Ingénieur Développement",30,IF(Septembre[[#This Row],[Qui]]="Ingénieur Mécanique",34,""))))) -> 68 | K27: =IF(Septembre[[#This Row],[TPS Cumul (h)]]>0,Septembre[[#This Row],[Charge Initiale (h)]]*Septembre[[#This Row],[Prix de revien unitaire(€)]],0) -> 0 | L27: =Septembre[[#This Row],[CR (h)]]*Septembre[[#This Row],[Prix de revien unitaire(€)]] -> 136 | M27: =Septembre[[#This Row],[Prix de revien unitaire(€)]]*Septembre[[#This Row],[TPS Cumul (h)]] -> 0 | N27: Non
A28: Livraison | B28: Rédaction du document de comparaison norme IEC61131 et IEC 61499 | C28: Chef de projet | D28: 3 | E28: 0 | F28: =Septembre[[#This Row],[TPS Période(h)]] -> 0 | G28: =IF(N28="Non",MAX(Septembre[[#This Row],[Charge Initiale (h)]]-Septembre[[#This Row],[TPS Cumul (h)]],0),0) -> 3 | H28: =Septembre[[#This Row],[TPS Cumul (h)]]+Septembre[[#This Row],[Reste à passer (h) ]] -> 3 | I28: =Septembre[[#This Row],[CR (h)]] - Septembre[[#This Row],[Charge Initiale (h)]] -> 0 | J28: =IF(Septembre[[#This Row],[Qui]]="Chef de projet","68",IF(Septembre[[#This Row],[Qui]]="Ingénieur Electronique","32",IF(Septembre[[#This Row],[Qui]]="Ingénieur qualité","36",IF(Septembre[[#This Row],[Qui]]="Ingénieur Développement",30,IF(Septembre[[#This Row],[Qui]]="Ingénieur Mécanique",34,""))))) -> 68 | K28: =IF(Septembre[[#This Row],[TPS Cumul (h)]]>0,Septembre[[#This Row],[Charge Initiale (h)]]*Septembre[[#This Row],[Prix de revien unitaire(€)]],0) -> 0 | L28: =Septembre[[#This Row],[CR (h)]]*Septembre[[#This Row],[Prix de revien unitaire(€)]] -> 204 | M28: =Septembre[[#This Row],[Prix de revien unitaire(€)]]*Septembre[[#This Row],[TPS Cumul (h)]] -> 0 | N28: Non
B29: Remise du simulateur fonctionnel EAE et Factory IO (IEC61499) | C29: Chef de projet | D29: 0 | E29: 0 | F29: =Septembre[[#This Row],[TPS Période(h)]] -> 0 | G29: =IF(N29="Non",MAX(Septembre[[#This Row],[Charge Initiale (h)]]-Septembre[[#This Row],[TPS Cumul (h)]],0),0) -> 0 | H29: =Septembre[[#This Row],[TPS Cumul (h)]]+Septembre[[#This Row],[Reste à passer (h) ]] -> 0 | I29: =Septembre[[#This Row],[CR (h)]] - Septembre[[#This Row],[Charge Initiale (h)]] -> 0 | J29: =IF(Septembre[[#This Row],[Qui]]="Chef de projet","68",IF(Septembre[[#This Row],[Qui]]="Ingénieur Electronique","32",IF(Septembre[[#This Row],[Qui]]="Ingénieur qualité","36",IF(Septembre[[#This Row],[Qui]]="Ingénieur Développement",30,IF(Septembre[[#This Row],[Qui]]="Ingénieur Mécanique",34,""))))) -> 68 | K29: =IF(Septembre[[#This Row],[TPS Cumul (h)]]>0,Septembre[[#This Row],[Charge Initiale (h)]]*Septembre[[#This Row],[Prix de revien unitaire(€)]],0) -> 0 | L29: =Septembre[[#This Row],[CR (h)]]*Septembre[[#This Row],[Prix de revien unitaire(€)]] -> 0 | M29: =Septembre[[#This Row],[Prix de revien unitaire(€)]]*Septembre[[#This Row],[TPS Cumul (h)]] -> 0 | N29: Non
B30: Remise du simulateur fonctionnel EAE et Factory IO (IEC61131) | C30: Chef de projet | D30: 0 | E30: 0 | F30: =Septembre[[#This Row],[TPS Période(h)]] -> 0 | G30: =IF(N30="Non",MAX(Septembre[[#This Row],[Charge Initiale (h)]]-Septembre[[#This Row],[TPS Cumul (h)]],0),0) -> 0 | H30: =Septembre[[#This Row],[TPS Cumul (h)]]+Septembre[[#This Row],[Reste à passer (h) ]] -> 0 | I30: =Septembre[[#This Row],[CR (h)]] - Septembre[[#This Row],[Charge Initiale (h)]] -> 0 | J30: =IF(Septembre[[#This Row],[Qui]]="Chef de projet","68",IF(Septembre[[#This Row],[Qui]]="Ingénieur Electronique","32",IF(Septembre[[#This Row],[Qui]]="Ingénieur qualité","36",IF(Septembre[[#This Row],[Qui]]="Ingénieur Développement",30,IF(Septembre[[#This Row],[Qui]]="Ingénieur Mécanique",34,""))))) -> 68 | K30: =IF(Septembre[[#This Row],[TPS Cumul (h)]]>0,Septembre[[#This Row],[Charge Initiale (h)]]*Septembre[[#This Row],[Prix de revien unitaire(€)]],0) -> 0 | L30: =Septembre[[#This Row],[CR (h)]]*Septembre[[#This Row],[Prix de revien unitaire(€)]] -> 0 | M30: =Septembre[[#This Row],[Prix de revien unitaire(€)]]*Septembre[[#This Row],[TPS Cumul (h)]] -> 0 | N30: Non
B31: Total | D31: =SUBTOTAL(109,Septembre[Charge Initiale (h)]) -> 115 | E31: =SUBTOTAL(109,Septembre[TPS Période(h)]) -> 16 | F31: =SUBTOTAL(109,Septembre[TPS Cumul (h)]) -> 16 | G31: =SUBTOTAL(109,Septembre[Reste à passer (h) ]) -> 99 | H31: =SUBTOTAL(109,Septembre[CR (h)]) -> 115 | I31: =SUBTOTAL(109,Septembre[ Ecart de charge (h)]) -> 0 | J31: =SUBTOTAL(109,Septembre[Prix de revien unitaire(€)]) -> 0 | K31: =SUBTOTAL(109,Septembre[Coût Initial (€)]) -> 1088 | L31: =SUBTOTAL(109,Septembre[Coût Révisé (€)]) -> 7820 | M31: =SUBTOTAL(109,Septembre[Coût Réel]) -> 1088
B35: Rôles | C35: Quantité d'heure | D35: PRU | N35: Validation Liste
B36: Chef de Projet | C36: =SUMIFS(Septembre[Charge Initiale (h)], Septembre[Qui], "Chef de Projet") -> 115 | D36: 68 | N36: Oui
B37: Total | C37: =SUM(C36:C36) -> 115 | D37: 8160

Sheet Octobre
A1: Phase | B1: Tâche | C1: Qui | D1: Charge Initiale (h) | E1: TPS Période(h) | F1: TPS Cumul (h) | G1: Reste à passer (h) | H1: CR (h) | I1: Ecart de charge (h) | J1: Prix de revien unitaire(€) | K1: Coût Initial (€) | L1: Coût Révisé (€) | M1: Coût Réel | N1: Validation
A2: Initialisation | B2: Fiche d'Ouverture de Projet | C2: Chef de projet | D2: 1 | E2: 1 | F2: =Octobre[[#This Row],[TPS Période(h)]] -> 1 | G2: =IF(N2="Non",MAX(Octobre[[#This Row],[Charge Initiale (h)]]-Octobre[[#This Row],[TPS Cumul (h)]],0),0) -> 0 | H2: =Octobre[[#This Row],[TPS Cumul (h)]]+Octobre[[#This Row],[Reste à passer (h) ]] -> 1 | I2: =Octobre[[#This Row],[CR (h)]] - Octobre[[#This Row],[Charge Initiale (h)]] -> 0 | J2: =IF(Octobre[[#This Row],[Qui]]="Chef de projet","68",IF(Octobre[[#This Row],[Qui]]="Ingénieur Electronique","32",IF(Octobre[[#This Row],[Qui]]="Ingénieur qualité","36",IF(Octobre[[#This Row],[Qui]]="Ingénieur Développement",30,IF(Octobre[[#This Row],[Qui]]="Ingénieur Mécanique",34,""))))) -> 68 | K2: =IF(Octobre[[#This Row],[TPS Cumul (h)]]>0,Octobre[[#This Row],[Charge Initiale (h)]]*Octobre[[#This Row],[Prix de revien unitaire(€)]],0) -> 68 | L2: =Octobre[[#This Row],[CR (h)]]*Octobre[[#This Row],[Prix de revien unitaire(€)]] -> 68 | M2: =Octobre[[#This Row],[Prix de revien unitaire(€)]]*Octobre[[#This Row],[TPS Cumul (h)]] -> 68 | N2: Oui
B3: Plan de développement | C3: Chef de projet | D3: 10 | E3: 10 | F3: =Octobre[[#This Row],[TPS Période(h)]] -> 10 | G3: =IF(N3="Non",MAX(Octobre[[#This Row],[Charge Initiale (h)]]-Octobre[[#This Row],[TPS Cumul (h)]],0),0) -> 0 | H3: =Octobre[[#This Row],[TPS Cumul (h)]]+Octobre[[#This Row],[Reste à passer (h) ]] -> 10 | I3: =Octobre[[#This Row],[CR (h)]] - Octobre[[#This Row],[Charge Initiale (h)]] -> 0 | J3: =IF(Octobre[[#This Row],[Qui]]="Chef de projet","68",IF(Octobre[[#This Row],[Qui]]="Ingénieur Electronique","32",IF(Octobre[[#This Row],[Qui]]="Ingénieur qualité","36",IF(Octobre[[#This Row],[Qui]]="Ingénieur Développement",30,IF(Octobre[[#This Row],[Qui]]="Ingénieur Mécanique",34,""))))) -> 68 | K3: =IF(Octobre[[#This Row],[TPS Cumul (h)]]>0,Octobre[[#This Row],[Charge Initiale (h)]]*Octobre[[#This Row],[Prix de revien unitaire(€)]],0) -> 680 | L3: =Octobre[[#This Row],[CR (h)]]*Octobre[[#This Row],[Prix de revien unitaire(€)]] -> 680 | M3: =Octobre[[#This Row],[Prix de revien unitaire(€)]]*Octobre[[#This Row],[TPS Cumul (h)]] -> 680 | N3: Oui
A4: Spécifications | B4: SPEC | C4: Chef de projet | D4: 5 | E4: 5 | F4: =Octobre[[#This Row],[TPS Période(h)]] -> 5 | G4: =IF(N4="Non",MAX(Octobre[[#This Row],[Charge Initiale (h)]]-Octobre[[#This Row],[TPS Cumul (h)]],0),0) -> 0 | H4: =Octobre[[#This Row],[TPS Cumul (h)]]+Octobre[[#This Row],[Reste à passer (h) ]] -> 5 | I4: =Octobre[[#This Row],[CR (h)]] - Octobre[[#This Row],[Charge Initiale (h)]] -> 0 | J4: =IF(Octobre[[#This Row],[Qui]]="Chef de projet","68",IF(Octobre[[#This Row],[Qui]]="Ingénieur Electronique","32",IF(Octobre[[#This Row],[Qui]]="Ingénieur qualité","36",IF(Octobre[[#This Row],[Qui]]="Ingénieur Développement",30,IF(Octobre[[#This Row],[Qui]]="Ingénieur Mécanique",34,""))))) -> 68 | K4: =IF(Octobre[[#This Row],[TPS Cumul (h)]]>0,Octobre[[#This Row],[Charge Initiale (h)]]*Octobre[[#This Row],[Prix de revien unitaire(€)]],0) -> 340 | L4: =Octobre[[#This Row],[CR (h)]]*Octobre[[#This Row],[Prix de revien unitaire(€)]] -> 340 | M4: =Octobre[[#This Row],[Prix de revien unitaire(€)]]*Octobre[[#This Row],[TPS Cumul (h)]] -> 340 | N4: Oui
B5: Analyse norme IEC61131 | C5: Chef de projet | D5: 1 | F5: =Octobre[[#This Row],[TPS Période(h)]] -> 0 | G5: =IF(N5="Non",MAX(Octobre[[#This Row],[Charge Initiale (h)]]-Octobre[[#This Row],[TPS Cumul (h)]],0),0) -> 1 | H5: =Octobre[[#This Row],[TPS Cumul (h)]]+Octobre[[#This Row],[Reste à passer (h) ]] -> 1 | I5: =Octobre[[#This Row],[CR (h)]] - Octobre[[#This Row],[Charge Initiale (h)]] -> 0 | J5: =IF(Octobre[[#This Row],[Qui]]="Chef de projet","68",IF(Octobre[[#This Row],[Qui]]="Ingénieur Electronique","32",IF(Octobre[[#This Row],[Qui]]="Ingénieur qualité","36",IF(Octobre[[#This Row],[Qui]]="Ingénieur Développement",30,IF(Octobre[[#This Row],[Qui]]="Ingénieur Mécanique",34,""))))) -> 68 | K5: =IF(Octobre[[#This Row],[TPS Cumul (h)]]>0,Octobre[[#This Row],[Charge Initiale (h)]]*Octobre[[#This Row],[Prix de revien unitaire(€)]],0) -> 0 | L5: =Octobre[[#This Row],[CR (h)]]*Octobre[[#This Row],[Prix de revien unitaire(€)]] -> 68 | M5: =Octobre[[#This Row],[Prix de revien unitaire(€)]]*Octobre[[#This Row],[TPS Cumul (h)]] -> 0 | N5: Non
B6: Analyse norme IEC61499 | C6: Chef de projet | D6: 2 | F6: =Octobre[[#This Row],[TPS Période(h)]] -> 0 | G6: =IF(N6="Non",MAX(Octobre[[#This Row],[Charge Initiale (h)]]-Octobre[[#This Row],[TPS Cumul (h)]],0),0) -> 2 | H6: =Octobre[[#This Row],[TPS Cumul (h)]]+Octobre[[#This Row],[Reste à passer (h) ]] -> 2 | I6: =Octobre[[#This Row],[CR (h)]] - Octobre[[#This Row],[Charge Initiale (h)]] -> 0 | J6: =IF(Octobre[[#This Row],[Qui]]="Chef de projet","68",IF(Octobre[[#This Row],[Qui]]="Ingénieur Electronique","32",IF(Octobre[[#This Row],[Qui]]="Ingénieur qualité","36",IF(Octobre[[#This Row],[Qui]]="Ingénieur Développement",30,IF(Octobre[[#This Row],[Qui]]="Ingénieur Mécanique",34,""))))) -> 68 | K6: =IF(Octobre[[#This Row],[TPS Cumul (h)]]>0,Octobre[[#This Row],[Charge Initiale (h)]]*Octobre[[#This Row],[Prix de revien unitaire(€)]],0) -> 0 | L6: =Octobre[[#This Row],[CR (h)]]*Octobre[[#This Row],[Prix de revien unitaire(€)]] -> 136 | M6: =Octobre[[#This Row],[Prix de revien unitaire(€)]]*Octobre[[#This Row],[TPS Cumul (h)]] -> 0 | N6: Non
B7: Analyse du fonctionnement du centre de tri de pièce FactoryIO | C7: Chef de projet | D7: 2 | E7: 1 | F7: =Octobre[[#This Row],[TPS Période(h)]] -> 1 | G7: =IF(N7="Non",MAX(Octobre[[#This Row],[Charge Initiale (h)]]-Octobre[[#This Row],[TPS Cumul (h)]],0),0) -> 0 | H7: =Octobre[[#This Row],[TPS Cumul (h)]]+Octobre[[#This Row],[Reste à passer (h) ]] -> 1 | I7: =Octobre[[#This Row],[CR (h)]] - Octobre[[#This Row],[Charge Initiale (h)]] -> -1 | J7: =IF(Octobre[[#This Row],[Qui]]="Chef de projet","68",IF(Octobre[[#This Row],[Qui]]="Ingénieur Electronique","32",IF(Octobre[[#This Row],[Qui]]="Ingénieur qualité","36",IF(Octobre[[#This Row],[Qui]]="Ingénieur Développement",30,IF(Octobre[[#This Row],[Qui]]="Ingénieur Mécanique",34,""))))) -> 68 | K7: =IF(Octobre[[#This Row],[TPS Cumul (h)]]>0,Octobre[[#This Row],[Charge Initiale (h)]]*Octobre[[#This Row],[Prix de revien unitaire(€)]],0) -> 136 | L7: =Octobre[[#This Row],[CR (h)]]*Octobre[[#This Row],[Prix de revien unitaire(€)]] -> 68 | M7: =Octobre[[#This Row],[Prix de revien unitaire(€)]]*Octobre[[#This Row],[TPS Cumul (h)]] -> 68 | N7: Oui
B8: Méthodologie de programmation du centre de tri de pièce (Norme IEC61131) | C8: Chef de projet | D8: 2 | E8: 1 | F8: =Octobre[[#This Row],[TPS Période(h)]] -> 1 | G8: =IF(N8="Non",MAX(Octobre[[#This Row],[Charge Initiale (h)]]-Octobre[[#This Row],[TPS Cumul (h)]],0),0) -> 0 | H8: =Octobre[[#This Row],[TPS Cumul (h)]]+Octobre[[#This Row],[Reste à passer (h) ]] -> 1 | I8: =Octobre[[#This Row],[CR (h)]] - Octobre[[#This Row],[Charge Initiale (h)]] -> -1 | J8: =IF(Octobre[[#This Row],[Qui]]="Chef de projet","68",IF(Octobre[[#This Row],[Qui]]="Ingénieur Electronique","32",IF(Octobre[[#This Row],[Qui]]="Ingénieur qualité","36",IF(Octobre[[#This Row],[Qui]]="Ingénieur Développement",30,IF(Octobre[[#This Row],[Qui]]="Ingénieur Mécanique",34,""))))) -> 68 | K8: =IF(Octobre[[#This Row],[TPS Cumul (h)]]>0,Octobre[[#This Row],[Charge Initiale (h)]]*Octobre[[#This Row],[Prix de revien unitaire(€)]],0) -> 136 | L8: =Octobre[[#This Row],[CR (h)]]*Octobre[[#This Row],[Prix de revien unitaire(€)]] -> 68 | M8: =Octobre[[#This Row],[Prix de revien unitaire(€)]]*Octobre[[#This Row],[TPS Cumul (h)]] -> 68 | N8: Oui
B9: Méthodologie de programmation du centre de tri de pièce (Norme IEC61499) | C9: Chef de projet | D9: 2 | F9: =Octobre[[#This Row],[TPS Période(h)]] -> 0 | G9: =IF(N9="Non",MAX(Octobre[[#This Row],[Charge Initiale (h)]]-Octobre[[#This Row],[TPS Cumul (h)]],0),0) -> 2 | H9: =Octobre[[#This Row],[TPS Cumul (h)]]+Octobre[[#This Row],[Reste à passer (h) ]] -> 2 | I9: =Octobre[[#This Row],[CR (h)]] - Octobre[[#This Row],[Charge Initiale (h)]] -> 0 | J9: =IF(Octobre[[#This Row],[Qui]]="Chef de projet","68",IF(Octobre[[#This Row],[Qui]]="Ingénieur Electronique","32",IF(Octobre[[#This Row],[Qui]]="Ingénieur qualité","36",IF(Octobre[[#This Row],[Qui]]="Ingénieur Développement",30,IF(Octobre[[#This Row],[Qui]]="Ingénieur Mécanique",34,""))))) -> 68 | K9: =IF(Octobre[[#This Row],[TPS Cumul (h)]]>0,Octobre[[#This Row],[Charge Initiale (h)]]*Octobre[[#This Row],[Prix de revien unitaire(€)]],0) -> 0 | L9: =Octobre[[#This Row],[CR (h)]]*Octobre[[#This Row],[Prix de revien unitaire(€)]] -> 136 | M9: =Octobre[[#This Row],[Prix de revien unitaire(€)]]*Octobre[[#This Row],[TPS Cumul (h)]] -> 0 | N9: Non
A10: Conception générale | B10: IEC61131 - Grafcet de niveau 1 | C10: Chef de projet | D10: 4 | E10: 3 | F10: =Octobre[[#This Row],[TPS Période(h)]] -> 3 | G10: =IF(N10="Non",MAX(Octobre[[#This Row],[Charge Initiale (h)]]-Octobre[[#This Row],[TPS Cumul (h)]],0),0) -> 1 | H10: =Octobre[[#This Row],[TPS Cumul (h)]]+Octobre[[#This Row],[Reste à passer (h) ]] -> 4 | I10: =Octobre[[#This Row],[CR (h)]] - Octobre[[#This Row],[Charge Initiale (h)]] -> 0 | J10: =IF(Octobre[[#This Row],[Qui]]="Chef de projet","68",IF(Octobre[[#This Row],[Qui]]="Ingénieur Electronique","32",IF(Octobre[[#This Row],[Qui]]="Ingénieur qualité","36",IF(Octobre[[#This Row],[Qui]]="Ingénieur Développement",30,IF(Octobre[[#This Row],[Qui]]="Ingénieur Mécanique",34,""))))) -> 68 | K10: =IF(Octobre[[#This Row],[TPS Cumul (h)]]>0,Octobre[[#This Row],[Charge Initiale (h)]]*Octobre[[#This Row],[Prix de revien unitaire(€)]],0) -> 272 | L10: =Octobre[[#This Row],[CR (h)]]*Octobre[[#This Row],[Prix de revien unitaire(€)]] -> 272 | M10: =Octobre[[#This Row],[Prix de revien unitaire(€)]]*Octobre[[#This Row],[TPS Cumul (h)]] -> 204 | N10: Non
B11: IEC61499 - Bloc fonctionnel général | C11: Chef de projet | D11: 4 | F11: =Octobre[[#This Row],[TPS Période(h)]] -> 0 | G11: =IF(N11="Non",MAX(Octobre[[#This Row],[Charge Initiale (h)]]-Octobre[[#This Row],[TPS Cumul (h)]],0),0) -> 4 | H11: =Octobre[[#This Row],[TPS Cumul (h)]]+Octobre[[#This Row],[Reste à passer (h) ]] -> 4 | I11: =Octobre[[#This Row],[CR (h)]] - Octobre[[#This Row],[Charge Initiale (h)]] -> 0 | J11: =IF(Octobre[[#This Row],[Qui]]="Chef de projet","68",IF(Octobre[[#This Row],[Qui]]="Ingénieur Electronique","32",IF(Octobre[[#This Row],[Qui]]="Ingénieur qualité","36",IF(Octobre[[#This Row],[Qui]]="Ingénieur Développement",30,IF(Octobre[[#This Row],[Qui]]="Ingénieur Mécanique",34,""))))) -> 68 | K11: =IF(Octobre[[#This Row],[TPS Cumul (h)]]>0,Octobre[[#This Row],[Charge Initiale (h)]]*Octobre[[#This Row],[Prix de revien unitaire(€)]],0) -> 0 | L11: =Octobre[[#This Row],[CR (h)]]*Octobre[[#This Row],[Prix de revien unitaire(€)]] -> 272 | M11: =Octobre[[#This Row],[Prix de revien unitaire(€)]]*Octobre[[#This Row],[TPS Cumul (h)]] -> 0 | N11: Non
B12: Fonctionnement général du centre de tri de pièce | C12: Chef de projet | D12: 1 | E12: 3 | F12: =Octobre[[#This Row],[TPS Période(h)]] -> 3 | G12: =IF(N12="Non",MAX(Octobre[[#This Row],[Charge Initiale (h)]]-Octobre[[#This Row],[TPS Cumul (h)]],0),0) -> 0 | H12: =Octobre[[#This Row],[TPS Cumul (h)]]+Octobre[[#This Row],[Reste à passer (h) ]] -> 3 | I12: =Octobre[[#This Row],[CR (h)]] - Octobre[[#This Row],[Charge Initiale (h)]] -> 2 | J12: =IF(Octobre[[#This Row],[Qui]]="Chef de projet","68",IF(Octobre[[#This Row],[Qui]]="Ingénieur Electronique","32",IF(Octobre[[#This Row],[Qui]]="Ingénieur qualité","36",IF(Octobre[[#This Row],[Qui]]="Ingénieur Développement",30,IF(Octobre[[#This Row],[Qui]]="Ingénieur Mécanique",34,""))))) -> 68 | K12: =IF(Octobre[[#This Row],[TPS Cumul (h)]]>0,Octobre[[#This Row],[Charge Initiale (h)]]*Octobre[[#This Row],[Prix de revien unitaire(€)]],0) -> 68 | L12: =Octobre[[#This Row],[CR (h)]]*Octobre[[#This Row],[Prix de revien unitaire(€)]] -> 204 | M12: =Octobre[[#This Row],[Prix de revien unitaire(€)]]*Octobre[[#This Row],[TPS Cumul (h)]] -> 204 | N12: Non
B13: Liste des capteurs Centre de tri de pièce | C13: Chef de projet | D13: 2 | E13: 1 | F13: =Octobre[[#This Row],[TPS Période(h)]] -> 1 | G13: =IF(N13="Non",MAX(Octobre[[#This Row],[Charge Initiale (h)]]-Octobre[[#This Row],[TPS Cumul (h)]],0),0) -> 1 | H13: =Octobre[[#This Row],[TPS Cumul (h)]]+Octobre[[#This Row],[Reste à passer (h) ]] -> 2 | I13: =Octobre[[#This Row],[CR (h)]] - Octobre[[#This Row],[Charge Initiale (h)]] -> 0 | J13: =IF(Octobre[[#This Row],[Qui]]="Chef de projet","68",IF(Octobre[[#This Row],[Qui]]="Ingénieur Electronique","32",IF(Octobre[[#This Row],[Qui]]="Ingénieur qualité","36",IF(Octobre[[#This Row],[Qui]]="Ingénieur Développement",30,IF(Octobre[[#This Row],[Qui]]="Ingénieur Mécanique",34,""))))) -> 68 | K13: =IF(Octobre[[#This Row],[TPS Cumul (h)]]>0,Octobre[[#This Row],[Charge Initiale (h)]]*Octobre[[#This Row],[Prix de revien unitaire(€)]],0) -> 136 | L13: =Octobre[[#This Row],[CR (h)]]*Octobre[[#This Row],[Prix de revien unitaire(€)]] -> 136 | M13: =Octobre[[#This Row],[Prix de revien unitaire(€)]]*Octobre[[#This Row],[TPS Cumul (h)]] -> 68 | N13: Non
A14: Conception détaillé | B14: IEC 61499 - Bloc fonctionnel détaillée | C14: Chef de projet | D14: 7 | F14: =Octobre[[#This Row],[TPS Période(h)]] -> 0 | G14: =IF(N14="Non",MAX(Octobre[[#This Row],[Charge Initiale (h)]]-Octobre[[#This Row],[TPS Cumul (h)]],0),0) -> 7 | H14: =Octobre[[#This Row],[TPS Cumul (h)]]+Octobre[[#This Row],[Reste à passer (h) ]] -> 7 | I14: =Octobre[[#This Row],[CR (h)]] - Octobre[[#This Row],[Charge Initiale (h)]] -> 0 | J14: =IF(Octobre[[#This Row],[Qui]]="Chef de projet","68",IF(Octobre[[#This Row],[Qui]]="Ingénieur Electronique","32",IF(Octobre[[#This Row],[Qui]]="Ingénieur qualité","36",IF(Octobre[[#This Row],[Qui]]="Ingénieur Développement",30,IF(Octobre[[#This Row],[Qui]]="Ingénieur Mécanique",34,""))))) -> 68 | K14: =IF(Octobre[[#This Row],[TPS Cumul (h)]]>0,Octobre[[#This Row],[Charge Initiale (h)]]*Octobre[[#This Row],[Prix de revien unitaire(€)]],0) -> 0 | L14: =Octobre[[#This Row],[CR (h)]]*Octobre[[#This Row],[Prix de revien unitaire(€)]] -> 476 | M14: =Octobre[[#This Row],[Prix de revien unitaire(€)]]*Octobre[[#This Row],[TPS Cumul (h)]] -> 0 | N14: Non
B15: IEC 61131 - Grafcet de niveau 2 | C15: Chef de projet | D15: 7 | E15: 2 | F15: =Octobre[[#This Row],[TPS Période(h)]] -> 2 | G15: =IF(N15="Non",MAX(Octobre[[#This Row],[Charge Initiale (h)]]-Octobre[[#This Row],[TPS Cumul (h)]],0),0) -> 0 | H15: =Octobre[[#This Row],[TPS Cumul (h)]]+Octobre[[#This Row],[Reste à passer (h) ]] -> 2 | I15: =Octobre[[#This Row],[CR (h)]] - Octobre[[#This Row],[Charge Initiale (h)]] -> -5 | J15: =IF(Octobre[[#This Row],[Qui]]="Chef de projet","68",IF(Octobre[[#This Row],[Qui]]="Ingénieur Electronique","32",IF(Octobre[[#This Row],[Qui]]="Ingénieur qualité","36",IF(Octobre[[#This Row],[Qui]]="Ingénieur Développement",30,IF(Octobre[[#This Row],[Qui]]="Ingénieur Mécanique",34,""))))) -> 68 | K15: =IF(Octobre[[#This Row],[TPS Cumul (h)]]>0,Octobre[[#This Row],[Charge Initiale (h)]]*Octobre[[#This Row],[Prix de revien unitaire(€)]],0) -> 476 | L15: =Octobre[[#This Row],[CR (h)]]*Octobre[[#This Row],[Prix de revien unitaire(€)]] -> 136 | M15: =Octobre[[#This Row],[Prix de revien unitaire(€)]]*Octobre[[#This Row],[TPS Cumul (h)]] -> 136
B16: Fonctionnement détaillé du centre de tri de pièce FactoryIO | C16: Chef de projet | D16: 4 | F16: =Octobre[[#This Row],[TPS Période(h)]] -> 0 | G16: =IF(N16="Non",MAX(Octobre[[#This Row],[Charge Initiale (h)]]-Octobre[[#This Row],[TPS Cumul (h)]],0),0) -> 4 | H16: =Octobre[[#This Row],[TPS Cumul (h)]]+Octobre[[#This Row],[Reste à passer (h) ]] -> 4 | I16: =Octobre[[#This Row],[CR (h)]] - Octobre[[#This Row],[Charge Initiale (h)]] -> 0 | J16: =IF(Octobre[[#This Row],[Qui]]="Chef de projet","68",IF(Octobre[[#This Row],[Qui]]="Ingénieur Electronique","32",IF(Octobre[[#This Row],[Qui]]="Ingénieur qualité","36",IF(Octobre[[#This Row],[Qui]]="Ingénieur Développement",30,IF(Octobre[[#This Row],[Qui]]="Ingénieur Mécanique",34,""))))) -> 68 | K16: =IF(Octobre[[#This Row],[TPS Cumul (h)]]>0,Octobre[[#This Row],[Charge Initiale (h)]]*Octobre[[#This Row],[Prix de revien unitaire(€)]],0) -> 0 | L16: =Octobre[[#This Row],[CR (h)]]*Octobre[[#This Row],[Prix de revien unitaire(€)]] -> 272 | M16: =Octobre[[#This Row],[Prix de revien unitaire(€)]]*Octobre[[#This Row],[TPS Cumul (h)]] -> 0 | N16: Non
B17: Tâble des variables centre de tri de pièce FactoryIO | C17: Chef de projet | D17: 3 | E17: 2 | F17: =Octobre[[#This Row],[TPS Période(h)]] -> 2 | G17: =IF(N17="Non",MAX(Octobre[[#This Row],[Charge Initiale (h)]]-Octobre[[#This Row],[TPS Cumul (h)]],0),0) -> 1 | H17: =Octobre[[#This Row],[TPS Cumul (h)]]+Octobre[[#This Row],[Reste à passer (h) ]] -> 3 | I17: =Octobre[[#This Row],[CR (h)]] - Octobre[[#This Row],[Charge Initiale (h)]] -> 0 | J17: =IF(Octobre[[#This Row],[Qui]]="Chef de projet","68",IF(Octobre[[#This Row],[Qui]]="Ingénieur Electronique","32",IF(Octobre[[#This Row],[Qui]]="Ingénieur qualité","36",IF(Octobre[[#This Row],[Qui]]="Ingénieur Développement",30,IF(Octobre[[#This Row],[Qui]]="Ingénieur Mécanique",34,""))))) -> 68 | K17: =IF(Octobre[[#This Row],[TPS Cumul (h)]]>0,Octobre[[#This Row],[Charge Initiale (h)]]*Octobre[[#This Row],[Prix de revien unitaire(€)]],0) -> 204 | L17: =Octobre[[#This Row],[CR (h)]]*Octobre[[#This Row],[Prix de revien unitaire(€)]] -> 204 | M17: =Octobre[[#This Row],[Prix de revien unitaire(€)]]*Octobre[[#This Row],[TPS Cumul (h)]] -> 136 | N17: Non
A18: Réalisation | B18: Programmation du centre de tri de pièce sur ECE | C18: Chef de projet | D18: 10 | F18: =Octobre[[#This Row],[TPS Période(h)]] -> 0 | G18: =IF(N18="Non",MAX(Octobre[[#This Row],[Charge Initiale (h)]]-Octobre[[#This Row],[TPS Cumul (h)]],0),0) -> 10 | H18: =Octobre[[#This Row],[TPS Cumul (h)]]+Octobre[[#This Row],[Reste à passer (h) ]] -> 10 | I18: =Octobre[[#This Row],[CR (h)]] - Octobre[[#This Row],[Charge Initiale (h)]] -> 0 | J18: =IF(Octobre[[#This Row],[Qui]]="Chef de projet","68",IF(Octobre[[#This Row],[Qui]]="Ingénieur Electronique","32",IF(Octobre[[#This Row],[Qui]]="Ingénieur qualité","36",IF(Octobre[[#This Row],[Qui]]="Ingénieur Développement",30,IF(Octobre[[#This Row],[Qui]]="Ingénieur Mécanique",34,""))))) -> 68 | K18: =IF(Octobre[[#This Row],[TPS Cumul (h)]]>0,Octobre[[#This Row],[Charge Initiale (h)]]*Octobre[[#This Row],[Prix de revien unitaire(€)]],0) -> 0 | L18: =Octobre[[#This Row],[CR (h)]]*Octobre[[#This Row],[Prix de revien unitaire(€)]] -> 680 | M18: =Octobre[[#This Row],[Prix de revien unitaire(€)]]*Octobre[[#This Row],[TPS Cumul (h)]] -> 0 | N18: Non
B19: Programmation du centre de tri de pièce sur EAE | C19: Chef de projet | D19: 10 | F19: =Octobre[[#This Row],[TPS Période(h)]] -> 0 | G19: =IF(N19="Non",MAX(Octobre[[#This Row],[Charge Initiale (h)]]-Octobre[[#This Row],[TPS Cumul (h)]],0),0) -> 10 | H19: =Octobre[[#This Row],[TPS Cumul (h)]]+Octobre[[#This Row],[Reste à passer (h) ]] -> 10 | I19: =Octobre[[#This Row],[CR (h)]] - Octobre[[#This Row],[Charge Initiale (h)]] -> 0 | J19: =IF(Octobre[[#This Row],[Qui]]="Chef de projet","68",IF(Octobre[[#This Row],[Qui]]="Ingénieur Electronique","32",IF(Octobre[[#This Row],[Qui]]="Ingénieur qualité","36",IF(Octobre[[#This Row],[Qui]]="Ingénieur Développement",30,IF(Octobre[[#This Row],[Qui]]="Ingénieur Mécanique",34,""))))) -> 68 | K19: =IF(Octobre[[#This Row],[TPS Cumul (h)]]>0,Octobre[[#This Row],[Charge Initiale (h)]]*Octobre[[#This Row],[Prix de revien unitaire(€)]],0) -> 0 | L19: =Octobre[[#This Row],[CR (h)]]*Octobre[[#This Row],[Prix de revien unitaire(€)]] -> 680 | M19: =Octobre[[#This Row],[Prix de revien unitaire(€)]]*Octobre[[#This Row],[TPS Cumul (h)]] -> 0 | N19: Non
B20: Rédaction du document de méthodologie de programmation sur la norme IEC61499 | C20: Chef de projet | D20: 3 | F20: =Octobre[[#This Row],[TPS Période(h)]] -> 0 | G20: =IF(N20="Non",MAX(Octobre[[#This Row],[Charge Initiale (h)]]-Octobre[[#This Row],[TPS Cumul (h)]],0),0) -> 3 | H20: =Octobre[[#This Row],[TPS Cumul (h)]]+Octobre[[#This Row],[Reste à passer (h) ]] -> 3 | I20: =Octobre[[#This Row],[CR (h)]] - Octobre[[#This Row],[Charge Initiale (h)]] -> 0 | J20: =IF(Octobre[[#This Row],[Qui]]="Chef de projet","68",IF(Octobre[[#This Row],[Qui]]="Ingénieur Electronique","32",IF(Octobre[[#This Row],[Qui]]="Ingénieur qualité","36",IF(Octobre[[#This Row],[Qui]]="Ingénieur Développement",30,IF(Octobre[[#This Row],[Qui]]="Ingénieur Mécanique",34,""))))) -> 68 | K20: =IF(Octobre[[#This Row],[TPS Cumul (h)]]>0,Octobre[[#This Row],[Charge Initiale (h)]]*Octobre[[#This Row],[Prix de revien unitaire(€)]],0) -> 0 | L20: =Octobre[[#This Row],[CR (h)]]*Octobre[[#This Row],[Prix de revien unitaire(€)]] -> 204 | M20: =Octobre[[#This Row],[Prix de revien unitaire(€)]]*Octobre[[#This Row],[TPS Cumul (h)]] -> 0 | N20: Non
B21: Correction (optionnel) | C21: Chef de projet | D21: 7 | F21: =Octobre[[#This Row],[TPS Période(h)]] -> 0 | G21: =IF(N21="Non",MAX(Octobre[[#This Row],[Charge Initiale (h)]]-Octobre[[#This Row],[TPS Cumul (h)]],0),0) -> 7 | H21: =Octobre[[#This Row],[TPS Cumul (h)]]+Octobre[[#This Row],[Reste à passer (h) ]] -> 7 | I21: =Octobre[[#This Row],[CR (h)]] - Octobre[[#This Row],[Charge Initiale (h)]] -> 0 | J21: =IF(Octobre[[#This Row],[Qui]]="Chef de projet","68",IF(Octobre[[#This Row],[Qui]]="Ingénieur Electronique","32",IF(Octobre[[#This Row],[Qui]]="Ingénieur qualité","36",IF(Octobre[[#This Row],[Qui]]="Ingénieur Développement",30,IF(Octobre[[#This Row],[Qui]]="Ingénieur Mécanique",34,""))))) -> 68 | K21: =IF(Octobre[[#This Row],[TPS Cumul (h)]]>0,Octobre[[#This Row],[Charge Initiale (h)]]*Octobre[[#This Row],[Prix de revien unitaire(€)]],0) -> 0 | L21: =Octobre[[#This Row],[CR (h)]]*Octobre[[#This Row],[Prix de revien unitaire(€)]] -> 476 | M21: =Octobre[[#This Row],[Prix de revien unitaire(€)]]*Octobre[[#This Row],[TPS Cumul (h)]] -> 0 | N21: Non
A22: Tests unitaires | B22: Test unitaire programme EAE | C22: Chef de projet | D22: 7 | F22: =Octobre[[#This Row],[TPS Période(h)]] -> 0 | G22: =IF(N22="Non",MAX(Octobre[[#This Row],[Charge Initiale (h)]]-Octobre[[#This Row],[TPS Cumul (h)]],0),0) -> 7 | H22: =Octobre[[#This Row],[TPS Cumul (h)]]+Octobre[[#This Row],[Reste à passer (h) ]] -> 7 | I22: =Octobre[[#This Row],[CR (h)]] - Octobre[[#This Row],[Charge Initiale (h)]] -> 0 | J22: =IF(Octobre[[#This Row],[Qui]]="Chef de projet","68",IF(Octobre[[#This Row],[Qui]]="Ingénieur Electronique","32",IF(Octobre[[#This Row],[Qui]]="Ingénieur qualité","36",IF(Octobre[[#This Row],[Qui]]="Ingénieur Développement",30,IF(Octobre[[#This Row],[Qui]]="Ingénieur Mécanique",34,""))))) -> 68 | K22: =IF(Octobre[[#This Row],[TPS Cumul (h)]]>0,Octobre[[#This Row],[Charge Initiale (h)]]*Octobre[[#This Row],[Prix de revien unitaire(€)]],0) -> 0 | L22: =Octobre[[#This Row],[CR (h)]]*Octobre[[#This Row],[Prix de revien unitaire(€)]] -> 476 | M22: =Octobre[[#This Row],[Prix de revien unitaire(€)]]*Octobre[[#This Row],[TPS Cumul (h)]] -> 0 | N22: Non
B23: Test unitaire programme ECE | C23: Chef de projet | D23: 2 | F23: =Octobre[[#This Row],[TPS Période(h)]] -> 0 | G23: =IF(N23="Non",MAX(Octobre[[#This Row],[Charge Initiale (h)]]-Octobre[[#This Row],[TPS Cumul (h)]],0),0) -> 2 | H23: =Octobre[[#This Row],[TPS Cumul (h)]]+Octobre[[#This Row],[Reste à passer (h) ]] -> 2 | I23: =Octobre[[#This Row],[CR (h)]] - Octobre[[#This Row],[Charge Initiale (h)]] -> 0 | J23: =IF(Octobre[[#This Row],[Qui]]="Chef de projet","68",IF(Octobre[[#This Row],[Qui]]="Ingénieur Electronique","32",IF(Octobre[[#This Row],[Qui]]="Ingénieur qualité","36",IF(Octobre[[#This Row],[Qui]]="Ingénieur Développement",30,IF(Octobre[[#This Row],[Qui]]="Ingénieur Mécanique",34,""))))) -> 68 | K23: =IF(Octobre[[#This Row],[TPS Cumul (h)]]>0,Octobre[[#This Row],[Charge Initiale (h)]]*Octobre[[#This Row],[Prix de revien unitaire(€)]],0) -> 0 | L23: =Octobre[[#This Row],[CR (h)]]*Octobre[[#This Row],[Prix de revien unitaire(€)]] -> 136 | M23: =Octobre[[#This Row],[Prix de revien unitaire(€)]]*Octobre[[#This Row],[TPS Cumul (h)]] -> 0 | N23: Non
